<?xml version="1.0" ?>
<!-- =================================================================================== -->
<!-- |    This document was autogenerated by xacro from /home/bren/ros_workspace/ics_bioloid/bioloid_interface/urdf/TypeA.xacro | -->
<!-- |    EDITING THIS FILE BY HAND IS NOT RECOMMENDED                                 | -->
<!-- =================================================================================== -->
<robot name="awesome-o" xmlns:xacro="http://www.ros.org/wiki/xacro">
  <link name="base_link">
    <visual>
      <geometry>
        <box size="0.11 0.05 0.12"/>
      </geometry>
    </visual>
  </link>
  <link name="R_shoulder">
    <visual>
      <geometry>
        <box size="0.03 0.04 0.03"/>
      </geometry>
      <origin rpy="0 0 0" xyz="0.0 0 0.00"/>
      <material name="blue">
        <color rgba="0 0 .8 1"/>
      </material>
    </visual>
  </link>
  <joint name="R_SAA" type="revolute">
    <parent link="base_link"/>
    <child link="R_shoulder"/>
    <origin rpy="1.5 0 0" xyz="0.07 0 0.03"/>
    <axis xyz="1 0 0"/>
    <limit effort="1000.0" lower="-3.14" upper="3.14" velocity="0.5"/>
  </joint>
  <link name="R_upper_arm">
    <visual>
      <geometry>
        <!--mesh filename="file:///home/local/AX12.dae" scale="0.0001 0.0001 0.0001"/-->
        <box size="0.03 0.04 0.09"/>
      </geometry>
      <material name="green">
        <color rgba="0 .8 0 1"/>
      </material>
      <origin rpy="0 0 0" xyz="0.00 0 -0.045"/>
    </visual>
  </link>
  <joint name="R_SFE" type="revolute">
    <parent link="R_shoulder"/>
    <child link="R_upper_arm"/>
    <origin rpy="0 -1.5 0" xyz="0.00 0 0.0"/>
    <axis xyz="0 -1 0"/>
    <limit effort="1000.0" lower="-3.14" upper="3.14" velocity="0.5"/>
  </joint>
  <link name="R_forearm">
    <visual>
      <geometry>
        <!--mesh filename="file:///home/local/AX12.dae" scale="0.0001 0.0001 0.0001"/-->
        <box size="0.03 0.04 0.09"/>
      </geometry>
      <material name="blue"/>
      <origin rpy="0 0 0" xyz="0.00 0 -0.045"/>
    </visual>
  </link>
  <joint name="R_EB" type="revolute">
    <parent link="R_upper_arm"/>
    <child link="R_forearm"/>
    <origin rpy="0 0 0" xyz="0.00 0 -0.08"/>
    <axis xyz="0 -1 0"/>
    <limit effort="1000.0" lower="-3.14" upper="3.14" velocity="0.5"/>
  </joint>
  <link name="L_shoulder">
    <visual>
      <geometry>
        <box size="0.03 0.04 0.03"/>
      </geometry>
      <origin rpy="0 0 0" xyz="0.0 0 0.00"/>
      <material name="blue">
        <color rgba="0 0 .8 1"/>
      </material>
    </visual>
  </link>
  <joint name="L_SAA" type="revolute">
    <parent link="base_link"/>
    <child link="L_shoulder"/>
    <origin rpy="1.5 0 0" xyz="-0.07 0 0.03"/>
    <axis xyz="-1 0 0"/>
    <limit effort="1000.0" lower="-3.14" upper="3.14" velocity="0.5"/>
  </joint>
  <link name="L_upper_arm">
    <visual>
      <geometry>
        <!--mesh filename="file:///home/local/AX12.dae" scale="0.0001 0.0001 0.0001"/-->
        <box size="0.03 0.04 0.09"/>
      </geometry>
      <material name="green">
        <color rgba="0 .8 0 1"/>
      </material>
      <origin rpy="0 0 0" xyz="0.00 0 -0.045"/>
    </visual>
  </link>
  <joint name="L_SFE" type="revolute">
    <parent link="L_shoulder"/>
    <child link="L_upper_arm"/>
    <origin rpy="0 1.5 0" xyz="0.00 0 0.0"/>
    <axis xyz="0 -1 0"/>
    <limit effort="1000.0" lower="-3.14" upper="3.14" velocity="0.5"/>
  </joint>
  <link name="L_forearm">
    <visual>
      <geometry>
        <!--mesh filename="file:///home/local/AX12.dae" scale="0.0001 0.0001 0.0001"/-->
        <box size="0.03 0.04 0.09"/>
      </geometry>
      <material name="blue"/>
      <origin rpy="0 0 0" xyz="0.00 0 -0.045"/>
    </visual>
  </link>
  <joint name="L_EB" type="revolute">
    <parent link="L_upper_arm"/>
    <child link="L_forearm"/>
    <origin rpy="0 0 0" xyz="0.00 0 -0.08"/>
    <axis xyz="0 -1 0"/>
    <limit effort="1000.0" lower="-3.14" upper="3.14" velocity="0.5"/>
  </joint>
  <link name="R_hip">
    <visual>
      <geometry>
        <box size="0.03 0.04 0.03"/>
      </geometry>
      <origin rpy="0 0 0" xyz="0.0 0 0.00"/>
      <material name="blue">
        <color rgba="0 0 .8 1"/>
      </material>
    </visual>
  </link>
  <joint name="R_HAA" type="revolute">
    <parent link="base_link"/>
    <child link="R_hip"/>
    <origin rpy="0 0 -0.7" xyz="0.03 0 -0.06"/>
    <axis xyz="0 0 -1"/>
    <limit effort="1000.0" lower="-3.14" upper="3.14" velocity="0.5"/>
  </joint>
  <link name="R_hip_split">
    <visual>
      <geometry>
        <box size="0.03 0.04 0.03"/>
      </geometry>
      <material name="red">
        <color rgba="1 .0 .0 1"/>
      </material>
      <origin rpy="0 0 0" xyz="0.00 0 -0.045"/>
    </visual>
  </link>
  <joint name="R_HR" type="revolute">
    <parent link="R_hip"/>
    <child link="R_hip_split"/>
    <origin rpy="0 0 0" xyz="0.00 0 0.0"/>
    <axis xyz="0 1 0"/>
    <limit effort="1000.0" lower="-3.14" upper="3.14" velocity="0.5"/>
  </joint>
  <link name="R_upper_leg">
    <visual>
      <geometry>
        <box size="0.03 0.04 0.09"/>
      </geometry>
      <material name="green"/>
      <origin rpy="0 0 0" xyz="0.00 0 -0.045"/>
    </visual>
  </link>
  <joint name="R_HFE" type="revolute">
    <parent link="R_hip_split"/>
    <child link="R_upper_leg"/>
    <origin rpy="0 0 0" xyz="0.00 0 0.0"/>
    <axis xyz="-1.0 0 0"/>
    <limit effort="1000.0" lower="-3.14" upper="3.14" velocity="0.5"/>
  </joint>
  <link name="R_calf">
    <visual>
      <geometry>
        <!--mesh filename="file:///home/local/AX12.dae" scale="0.0001 0.0001 0.0001"/-->
        <box size="0.03 0.04 0.09"/>
      </geometry>
      <material name="blue"/>
      <origin rpy="0 0 0" xyz="0.00 0 -0.045"/>
    </visual>
  </link>
  <joint name="R_KFE" type="revolute">
    <parent link="R_upper_leg"/>
    <child link="R_calf"/>
    <origin rpy="0 0 0" xyz="0.00 0 -0.08"/>
    <axis xyz="1.0 0 0"/>
    <limit effort="1000.0" lower="-3.14" upper="3.14" velocity="0.5"/>
  </joint>
  <link name="R_foot">
    <visual>
      <geometry>
        <box size="0.05 0.075 0.05"/>
      </geometry>
      <material name="green"/>
      <origin rpy="0 0 0" xyz="0.00 0 -0.045"/>
    </visual>
  </link>
  <joint name="R_AFE" type="revolute">
    <parent link="R_calf"/>
    <child link="R_foot"/>
    <origin rpy="0 0 0" xyz="0.00 0 -0.045"/>
    <axis xyz="1 0 0"/>
    <limit effort="1000.0" lower="-3.14" upper="3.14" velocity="0.5"/>
  </joint>
  <link name="R_foot_pad">
    <visual>
      <geometry>
        <box size="0.06 0.10 0.005"/>
      </geometry>
      <material name="blue"/>
      <origin rpy="0 0 0" xyz="0.00 0 -0.045"/>
    </visual>
  </link>
  <joint name="R_AR" type="revolute">
    <parent link="R_foot"/>
    <child link="R_foot_pad"/>
    <origin rpy="0 0 0" xyz="0.00 0 -0.03"/>
    <axis xyz="0 -1 0"/>
    <limit effort="1000.0" lower="-3.14" upper="3.14" velocity="0.5"/>
  </joint>
  <link name="L_hip">
    <visual>
      <geometry>
        <box size="0.03 0.04 0.03"/>
      </geometry>
      <origin rpy="0 0 0" xyz="0.0 0 0.00"/>
      <material name="blue">
        <color rgba="0 0 .8 1"/>
      </material>
    </visual>
  </link>
  <joint name="L_HAA" type="revolute">
    <parent link="base_link"/>
    <child link="L_hip"/>
    <origin rpy="0 0 0.7" xyz="-0.03 0 -0.06"/>
    <axis xyz="0 0 -1"/>
    <limit effort="1000.0" lower="-3.14" upper="3.14" velocity="0.5"/>
  </joint>
  <link name="L_hip_split">
    <visual>
      <geometry>
        <box size="0.03 0.04 0.03"/>
      </geometry>
      <material name="red">
        <color rgba="1 .0 .0 1"/>
      </material>
      <origin rpy="0 0 0" xyz="0.00 0 -0.045"/>
    </visual>
  </link>
  <joint name="L_HR" type="revolute">
    <parent link="L_hip"/>
    <child link="L_hip_split"/>
    <origin rpy="0 0 0" xyz="0.00 0 0.0"/>
    <axis xyz="0 1 0"/>
    <limit effort="1000.0" lower="-3.14" upper="3.14" velocity="0.5"/>
  </joint>
  <link name="L_upper_leg">
    <visual>
      <geometry>
        <box size="0.03 0.04 0.09"/>
      </geometry>
      <material name="green"/>
      <origin rpy="0 0 0" xyz="0.00 0 -0.045"/>
    </visual>
  </link>
  <joint name="L_HFE" type="revolute">
    <parent link="L_hip_split"/>
    <child link="L_upper_leg"/>
    <origin rpy="0 0 0" xyz="0.00 0 0.0"/>
    <axis xyz="1.0 0 0"/>
    <limit effort="1000.0" lower="-3.14" upper="3.14" velocity="0.5"/>
  </joint>
  <link name="L_calf">
    <visual>
      <geometry>
        <!--mesh filename="file:///home/local/AX12.dae" scale="0.0001 0.0001 0.0001"/-->
        <box size="0.03 0.04 0.09"/>
      </geometry>
      <material name="blue"/>
      <origin rpy="0 0 0" xyz="0.00 0 -0.045"/>
    </visual>
  </link>
  <joint name="L_KFE" type="revolute">
    <parent link="L_upper_leg"/>
    <child link="L_calf"/>
    <origin rpy="0 0 0" xyz="0.00 0 -0.08"/>
    <axis xyz="-1.0 0 0"/>
    <limit effort="1000.0" lower="-3.14" upper="3.14" velocity="0.5"/>
  </joint>
  <link name="L_foot">
    <visual>
      <geometry>
        <box size="0.05 0.075 0.05"/>
      </geometry>
      <material name="green"/>
      <origin rpy="0 0 0" xyz="0.00 0 -0.045"/>
    </visual>
  </link>
  <joint name="L_AFE" type="revolute">
    <parent link="L_calf"/>
    <child link="L_foot"/>
    <origin rpy="0 0 0" xyz="0.00 0 -0.045"/>
    <axis xyz="-1 0 0"/>
    <limit effort="1000.0" lower="-3.14" upper="3.14" velocity="0.5"/>
  </joint>
  <link name="L_foot_pad">
    <visual>
      <geometry>
        <box size="0.06 0.10 0.005"/>
      </geometry>
      <material name="blue"/>
      <origin rpy="0 0 0" xyz="0.00 0 -0.045"/>
    </visual>
  </link>
  <joint name="L_AR" type="revolute">
    <parent link="L_foot"/>
    <child link="L_foot_pad"/>
    <origin rpy="0 0 0" xyz="0.00 0 -0.03"/>
    <axis xyz="0 -1 0"/>
    <limit effort="1000.0" lower="-3.14" upper="3.14" velocity="0.5"/>
  </joint>
</robot>

